Success: no issues found in 4 source files
D104 Missing docstring in public package
--> db\__init__.py:1:1

D200 One-line docstring should fit on one line
 --> db\exceptions.py:1:1
  |
1 | / """
2 | | Custom database exceptions for the AI Typing Trainer application.
3 | | """
  | |___^
  |
help: Reformat to one line

D212 [*] Multi-line docstring summary should start at the first line
 --> db\exceptions.py:1:1
  |
1 | / """
2 | | Custom database exceptions for the AI Typing Trainer application.
3 | | """
  | |___^
  |
help: Remove whitespace after opening quotes

D102 Missing docstring in public method
  --> db\interfaces.py:19:9
   |
17 |     """
18 |
19 |     def execute(self, query: str, params: Tuple[object, ...] = ()) -> object:
   |         ^^^^^^^
20 |         ...
   |

D102 Missing docstring in public method
  --> db\interfaces.py:23:9
   |
22 |     @property
23 |     def execute_many_supported(self) -> bool:
   |         ^^^^^^^^^^^^^^^^^^^^^^
24 |         ...
   |

D102 Missing docstring in public method
  --> db\interfaces.py:26:9
   |
24 |         ...
25 |
26 |     def execute_many(self, query: str, params_seq: Iterable[Tuple[object, ...]]) -> object:
   |         ^^^^^^^^^^^^
27 |         ...
   |

Found 6 errors.
[*] 1 fixable with the `--fix` option (1 hidden fix can be enabled with the `--unsafe-fixes` option).
============================= test session starts =============================
platform win32 -- Python 3.13.2, pytest-8.4.1, pluggy-1.6.0 -- D:\SeanDevLocal\AITypingTrainer\.venv\Scripts\python.exe
cachedir: .pytest_cache
PySide6 6.9.1 -- Qt runtime 6.9.1 -- Qt compiled 6.9.1
rootdir: D:\SeanDevLocal\AITypingTrainer
configfile: pytest.ini
plugins: anyio-4.10.0, cov-6.2.1, mock-3.14.1, qt-4.5.0
collecting ... collected 40 items

tests/db/test_database_exceptions.py::TestDatabaseExceptions::test_connection_error PASSED [  2%]
tests/db/test_database_exceptions.py::TestDatabaseExceptions::test_foreign_key_violation PASSED [  5%]
tests/db/test_database_exceptions.py::TestDatabaseExceptions::test_schema_error PASSED [  7%]
tests/db/test_database_exceptions.py::TestDatabaseExceptions::test_constraint_violation PASSED [ 10%]
tests/db/test_database_exceptions.py::TestDatabaseExceptions::test_context_manager_handles_exceptions PASSED [ 12%]
tests/db/test_database_exceptions.py::TestDatabaseExceptions::test_table_not_found_error_select PASSED [ 15%]
tests/db/test_database_exceptions.py::TestDatabaseExceptions::test_table_not_found_error_insert PASSED [ 17%]
tests/db/test_database_exceptions.py::TestDatabaseExceptions::test_table_not_found_error_update PASSED [ 20%]
tests/db/test_database_exceptions.py::TestDatabaseExceptions::test_table_not_found_error_delete PASSED [ 22%]
tests/db/test_database_manager.py::TestDatabaseManagerInitialization::test_init_with_temp_file PASSED [ 25%]
tests/db/test_database_manager.py::TestDatabaseManagerInitialization::test_init_with_invalid_path_raises_error PASSED [ 27%]
tests/db/test_database_manager.py::TestDatabaseManagerInitialization::test_context_manager_cleans_up PASSED [ 30%]
tests/db/test_database_manager.py::TestDatabaseOperations::test_execute_create_table PASSED [ 32%]
tests/db/test_database_manager.py::TestDatabaseOperations::test_execute_insert PASSED [ 35%]
tests/db/test_database_manager.py::TestDatabaseOperations::test_fetchone_returns_none_for_no_results PASSED [ 37%]
tests/db/test_database_manager.py::TestDatabaseOperations::test_fetchall_returns_all_results PASSED [ 40%]
tests/db/test_database_manager.py::TestDatabaseOperations::test_fetchall_returns_empty_list_for_no_results PASSED [ 42%]
tests/db/test_database_manager.py::TestErrorHandling::test_table_not_found_error PASSED [ 45%]
tests/db/test_database_manager.py::TestErrorHandling::test_schema_error PASSED [ 47%]
tests/db/test_database_manager.py::TestErrorHandling::test_foreign_key_error PASSED [ 50%]
tests/db/test_database_manager.py::TestErrorHandling::test_constraint_error_unique PASSED [ 52%]
tests/db/test_database_manager.py::TestErrorHandling::test_constraint_error_not_null PASSED [ 55%]
tests/db/test_database_manager.py::TestExecuteMany::test_execute_many_insert_success_sqlite PASSED [ 57%]
tests/db/test_database_manager.py::TestExecuteMany::test_execute_many_pk_violation_sqlite PASSED [ 60%]
tests/db/test_database_manager.py::TestExecuteMany::test_execute_many_unique_violation_sqlite PASSED [ 62%]
tests/db/test_database_manager.py::TestExecuteMany::test_execute_many_not_null_violation_sqlite PASSED [ 65%]
tests/db/test_database_manager.py::TestExecuteMany::test_execute_many_table_not_found_sqlite PASSED [ 67%]
tests/db/test_database_manager.py::TestExecuteMany::test_execute_many_insert_success_cloud PASSED [ 70%]
tests/db/test_database_manager.py::TestExecuteMany::test_execute_many_method_options_sqlite PASSED [ 72%]
tests/db/test_database_manager.py::TestExecuteMany::test_execute_many_method_options_cloud[BulkMethod.VALUES-300-rows0] PASSED [ 75%]
tests/db/test_database_manager.py::TestExecuteMany::test_execute_many_method_options_cloud[BulkMethod.COPY-302-rows1] PASSED [ 77%]
tests/db/test_database_manager.py::TestExecuteMany::test_execute_many_method_options_cloud[BulkMethod.EXECUTEMANY-304-rows2] PASSED [ 80%]
tests/db/test_database_manager.py::TestExecuteMany::test_execute_many_method_options_cloud[BulkMethod.AUTO-305-rows3] PASSED [ 82%]
tests/db/test_database_manager.py::TestExecuteMany::test_postgres_bulk_insert_performance PASSED [ 85%]
tests/db/test_database_manager.py::TestExecuteMany::test_execute_many_pk_violation_cloud PASSED [ 87%]
tests/db/test_database_manager.py::TestExecuteMany::test_execute_many_unique_violation_cloud PASSED [ 90%]
tests/db/test_database_manager.py::TestExecuteMany::test_execute_many_not_null_violation_cloud PASSED [ 92%]
tests/db/test_database_manager.py::TestExecuteManyHelpers::test__bulk_executemany_sqlite_inserts PASSED [ 95%]
tests/db/test_database_manager.py::TestExecuteManyHelpers::test__bulk_execute_values_calls_psycopg2_extras PASSED [ 97%]
tests/db/test_database_manager.py::TestExecuteManyHelpers::test__bulk_copy_from_builds_tsv_and_calls_copy PASSED [100%]

============================= 40 passed in 23.77s =============================
============================= test session starts =============================
platform win32 -- Python 3.13.2, pytest-8.4.1, pluggy-1.6.0
PySide6 6.9.1 -- Qt runtime 6.9.1 -- Qt compiled 6.9.1
rootdir: D:\SeanDevLocal\AITypingTrainer
configfile: pytest.ini
plugins: anyio-4.10.0, cov-6.2.1, mock-3.14.1, qt-4.5.0
collected 40 items

tests\db\test_database_exceptions.py .........                           [ 22%]
tests\db\test_database_manager.py ...............................        [100%]

============================== warnings summary ===============================
tests/db/test_database_exceptions.py::TestDatabaseExceptions::test_constraint_violation
  C:\Python\Python313\Lib\traceback.py:797: ResourceWarning: unclosed database in <sqlite3.Connection object at 0x0000026C69CFE3E0>
    def _extract_caret_anchors_from_line_segment(segment):
  Enable tracemalloc to get traceback where the object was allocated.
  See https://docs.pytest.org/en/stable/how-to/capture-warnings.html#resource-warnings for more info.

tests/db/test_database_exceptions.py::TestDatabaseExceptions::test_constraint_violation
  C:\Python\Python313\Lib\traceback.py:797: ResourceWarning: unclosed database in <sqlite3.Connection object at 0x0000026C69CFE5C0>
    def _extract_caret_anchors_from_line_segment(segment):
  Enable tracemalloc to get traceback where the object was allocated.
  See https://docs.pytest.org/en/stable/how-to/capture-warnings.html#resource-warnings for more info.

tests/db/test_database_manager.py::TestExecuteMany::test_execute_many_insert_success_cloud
  D:\SeanDevLocal\AITypingTrainer\.venv\Lib\site-packages\botocore\configprovider.py:810: ResourceWarning: unclosed database in <sqlite3.Connection object at 0x0000026C69CFE6B0>
    def __init__(self, name, env):
  Enable tracemalloc to get traceback where the object was allocated.
  See https://docs.pytest.org/en/stable/how-to/capture-warnings.html#resource-warnings for more info.

tests/db/test_database_manager.py::TestExecuteMany::test_execute_many_insert_success_cloud
  D:\SeanDevLocal\AITypingTrainer\.venv\Lib\site-packages\botocore\configprovider.py:810: ResourceWarning: unclosed database in <sqlite3.Connection object at 0x0000026C69CFF010>
    def __init__(self, name, env):
  Enable tracemalloc to get traceback where the object was allocated.
  See https://docs.pytest.org/en/stable/how-to/capture-warnings.html#resource-warnings for more info.

tests/db/test_database_manager.py::TestExecuteMany::test_execute_many_insert_success_cloud
  D:\SeanDevLocal\AITypingTrainer\.venv\Lib\site-packages\botocore\configprovider.py:810: ResourceWarning: unclosed database in <sqlite3.Connection object at 0x0000026C69CFF2E0>
    def __init__(self, name, env):
  Enable tracemalloc to get traceback where the object was allocated.
  See https://docs.pytest.org/en/stable/how-to/capture-warnings.html#resource-warnings for more info.

tests/db/test_database_manager.py::TestExecuteMany::test_execute_many_insert_success_cloud
  D:\SeanDevLocal\AITypingTrainer\.venv\Lib\site-packages\botocore\configprovider.py:810: ResourceWarning: unclosed database in <sqlite3.Connection object at 0x0000026C69CFF3D0>
    def __init__(self, name, env):
  Enable tracemalloc to get traceback where the object was allocated.
  See https://docs.pytest.org/en/stable/how-to/capture-warnings.html#resource-warnings for more info.

tests/db/test_database_manager.py::TestExecuteMany::test_execute_many_insert_success_cloud
  D:\SeanDevLocal\AITypingTrainer\.venv\Lib\site-packages\botocore\configprovider.py:810: ResourceWarning: unclosed database in <sqlite3.Connection object at 0x0000026C69CFF1F0>
    def __init__(self, name, env):
  Enable tracemalloc to get traceback where the object was allocated.
  See https://docs.pytest.org/en/stable/how-to/capture-warnings.html#resource-warnings for more info.

tests/db/test_database_manager.py::TestExecuteMany::test_execute_many_insert_success_cloud
  D:\SeanDevLocal\AITypingTrainer\.venv\Lib\site-packages\botocore\configprovider.py:810: ResourceWarning: unclosed database in <sqlite3.Connection object at 0x0000026C69CFD300>
    def __init__(self, name, env):
  Enable tracemalloc to get traceback where the object was allocated.
  See https://docs.pytest.org/en/stable/how-to/capture-warnings.html#resource-warnings for more info.

tests/db/test_database_manager.py::TestExecuteMany::test_execute_many_insert_success_cloud
  D:\SeanDevLocal\AITypingTrainer\.venv\Lib\site-packages\botocore\configprovider.py:810: ResourceWarning: unclosed database in <sqlite3.Connection object at 0x0000026C69CFF790>
    def __init__(self, name, env):
  Enable tracemalloc to get traceback where the object was allocated.
  See https://docs.pytest.org/en/stable/how-to/capture-warnings.html#resource-warnings for more info.

tests/db/test_database_manager.py::TestExecuteMany::test_execute_many_insert_success_cloud
  D:\SeanDevLocal\AITypingTrainer\.venv\Lib\site-packages\botocore\configprovider.py:810: ResourceWarning: unclosed database in <sqlite3.Connection object at 0x0000026C69CFFA60>
    def __init__(self, name, env):
  Enable tracemalloc to get traceback where the object was allocated.
  See https://docs.pytest.org/en/stable/how-to/capture-warnings.html#resource-warnings for more info.

tests/db/test_database_manager.py::TestExecuteMany::test_execute_many_insert_success_cloud
  D:\SeanDevLocal\AITypingTrainer\.venv\Lib\site-packages\botocore\configprovider.py:810: ResourceWarning: unclosed database in <sqlite3.Connection object at 0x0000026C69CFFC40>
    def __init__(self, name, env):
  Enable tracemalloc to get traceback where the object was allocated.
  See https://docs.pytest.org/en/stable/how-to/capture-warnings.html#resource-warnings for more info.

tests/db/test_database_manager.py::TestExecuteMany::test_execute_many_insert_success_cloud
  D:\SeanDevLocal\AITypingTrainer\.venv\Lib\site-packages\botocore\configprovider.py:810: ResourceWarning: unclosed database in <sqlite3.Connection object at 0x0000026C69CFFD30>
    def __init__(self, name, env):
  Enable tracemalloc to get traceback where the object was allocated.
  See https://docs.pytest.org/en/stable/how-to/capture-warnings.html#resource-warnings for more info.

tests/db/test_database_manager.py::TestExecuteMany::test_execute_many_insert_success_cloud
  D:\SeanDevLocal\AITypingTrainer\.venv\Lib\site-packages\botocore\configprovider.py:810: ResourceWarning: unclosed database in <sqlite3.Connection object at 0x0000026C69CFFE20>
    def __init__(self, name, env):
  Enable tracemalloc to get traceback where the object was allocated.
  See https://docs.pytest.org/en/stable/how-to/capture-warnings.html#resource-warnings for more info.

tests/db/test_database_manager.py::TestExecuteMany::test_execute_many_insert_success_cloud
  D:\SeanDevLocal\AITypingTrainer\.venv\Lib\site-packages\botocore\configprovider.py:810: ResourceWarning: unclosed database in <sqlite3.Connection object at 0x0000026C69CFFF10>
    def __init__(self, name, env):
  Enable tracemalloc to get traceback where the object was allocated.
  See https://docs.pytest.org/en/stable/how-to/capture-warnings.html#resource-warnings for more info.

tests/db/test_database_manager.py::TestExecuteMany::test_execute_many_insert_success_cloud
  D:\SeanDevLocal\AITypingTrainer\.venv\Lib\site-packages\botocore\configprovider.py:810: ResourceWarning: unclosed database in <sqlite3.Connection object at 0x0000026C6AEF8040>
    def __init__(self, name, env):
  Enable tracemalloc to get traceback where the object was allocated.
  See https://docs.pytest.org/en/stable/how-to/capture-warnings.html#resource-warnings for more info.

tests/db/test_database_manager.py::TestExecuteMany::test_execute_many_insert_success_cloud
  D:\SeanDevLocal\AITypingTrainer\.venv\Lib\site-packages\botocore\configprovider.py:810: ResourceWarning: unclosed database in <sqlite3.Connection object at 0x0000026C6AEF8130>
    def __init__(self, name, env):
  Enable tracemalloc to get traceback where the object was allocated.
  See https://docs.pytest.org/en/stable/how-to/capture-warnings.html#resource-warnings for more info.

tests/db/test_database_manager.py::TestExecuteMany::test_execute_many_insert_success_cloud
  D:\SeanDevLocal\AITypingTrainer\.venv\Lib\site-packages\botocore\configprovider.py:810: ResourceWarning: unclosed database in <sqlite3.Connection object at 0x0000026C6AEF8220>
    def __init__(self, name, env):
  Enable tracemalloc to get traceback where the object was allocated.
  See https://docs.pytest.org/en/stable/how-to/capture-warnings.html#resource-warnings for more info.

-- Docs: https://docs.pytest.org/en/stable/how-to/capture-warnings.html
=============================== tests coverage ================================
_______________ coverage: platform win32, python 3.13.2-final-0 _______________

Name                     Stmts   Miss  Cover   Missing
------------------------------------------------------
db\__init__.py               0      0   100%
db\database_manager.py     472    104    78%   50-51, 120-121, 130-131, 157-160, 164, 264-275, 283-301, 338, 347, 413-416, 430-432, 435-438, 448, 460-465, 477, 532-534, 547, 552, 559-561, 563, 572, 574, 576, 581, 590-597, 622-623, 642, 670, 683-689, 703, 713-715, 728-730, 732, 775, 784, 819, 828-829, 839-841, 849-851, 856, 907-910, 933-944, 1290-1291
db\exceptions.py             8      0   100%
db\interfaces.py             3      3     0%   8-13
------------------------------------------------------
TOTAL                      483    107    78%
====================== 40 passed, 17 warnings in 23.94s =======================
